2024-11-08 13:33:53,143 - ERROR - Login failed - Invalid credentials or timeout
Traceback (most recent call last):
  File "/home/haseeb/xovolt/AutomatingTesting/tests/home.py", line 35, in login
    if page.wait_for_url(f"{base_url}/apps/clients/", timeout=10000):
       ^^^^^^^^^^^^^^^^^^^^^^^^^^^^^^^^^^^^^^^^^^^^^^^^^^^^^^^^^^^^^
  File "/home/haseeb/xovolt/AutomatingTesting/atvenv/lib/python3.11/site-packages/playwright/sync_api/_generated.py", line 9145, in wait_for_url
    self._sync(
  File "/home/haseeb/xovolt/AutomatingTesting/atvenv/lib/python3.11/site-packages/playwright/_impl/_sync_base.py", line 115, in _sync
    return task.result()
           ^^^^^^^^^^^^^
  File "/home/haseeb/xovolt/AutomatingTesting/atvenv/lib/python3.11/site-packages/playwright/_impl/_page.py", line 577, in wait_for_url
    return await self._main_frame.wait_for_url(**locals_to_params(locals()))
           ^^^^^^^^^^^^^^^^^^^^^^^^^^^^^^^^^^^^^^^^^^^^^^^^^^^^^^^^^^^^^^^^^
  File "/home/haseeb/xovolt/AutomatingTesting/atvenv/lib/python3.11/site-packages/playwright/_impl/_frame.py", line 233, in wait_for_url
    async with self.expect_navigation(
  File "/home/haseeb/xovolt/AutomatingTesting/atvenv/lib/python3.11/site-packages/playwright/_impl/_event_context_manager.py", line 33, in __aexit__
    await self._future
  File "/home/haseeb/xovolt/AutomatingTesting/atvenv/lib/python3.11/site-packages/playwright/_impl/_frame.py", line 208, in continuation
    event = await waiter.result()
            ^^^^^^^^^^^^^^^^^^^^^
playwright._impl._errors.TimeoutError: Timeout 10000ms exceeded.
=========================== logs ===========================
waiting for navigation to "http://localhost:3000/apps/clients/" until 'load'
============================================================
2024-11-08 13:33:53,146 - ERROR - Error in main function: Timeout 10000ms exceeded.
=========================== logs ===========================
waiting for navigation to "http://localhost:3000/apps/clients/" until 'load'
============================================================
Traceback (most recent call last):
  File "/home/haseeb/xovolt/AutomatingTesting/tests/home.py", line 52, in main
    if login(page):
       ^^^^^^^^^^^
  File "/home/haseeb/xovolt/AutomatingTesting/tests/home.py", line 44, in login
    raise e  # Re-raise the exception to handle it in the main function
    ^^^^^^^
  File "/home/haseeb/xovolt/AutomatingTesting/tests/home.py", line 35, in login
    if page.wait_for_url(f"{base_url}/apps/clients/", timeout=10000):
       ^^^^^^^^^^^^^^^^^^^^^^^^^^^^^^^^^^^^^^^^^^^^^^^^^^^^^^^^^^^^^
  File "/home/haseeb/xovolt/AutomatingTesting/atvenv/lib/python3.11/site-packages/playwright/sync_api/_generated.py", line 9145, in wait_for_url
    self._sync(
  File "/home/haseeb/xovolt/AutomatingTesting/atvenv/lib/python3.11/site-packages/playwright/_impl/_sync_base.py", line 115, in _sync
    return task.result()
           ^^^^^^^^^^^^^
  File "/home/haseeb/xovolt/AutomatingTesting/atvenv/lib/python3.11/site-packages/playwright/_impl/_page.py", line 577, in wait_for_url
    return await self._main_frame.wait_for_url(**locals_to_params(locals()))
           ^^^^^^^^^^^^^^^^^^^^^^^^^^^^^^^^^^^^^^^^^^^^^^^^^^^^^^^^^^^^^^^^^
  File "/home/haseeb/xovolt/AutomatingTesting/atvenv/lib/python3.11/site-packages/playwright/_impl/_frame.py", line 233, in wait_for_url
    async with self.expect_navigation(
  File "/home/haseeb/xovolt/AutomatingTesting/atvenv/lib/python3.11/site-packages/playwright/_impl/_event_context_manager.py", line 33, in __aexit__
    await self._future
  File "/home/haseeb/xovolt/AutomatingTesting/atvenv/lib/python3.11/site-packages/playwright/_impl/_frame.py", line 208, in continuation
    event = await waiter.result()
            ^^^^^^^^^^^^^^^^^^^^^
playwright._impl._errors.TimeoutError: Timeout 10000ms exceeded.
=========================== logs ===========================
waiting for navigation to "http://localhost:3000/apps/clients/" until 'load'
============================================================
